<?xml version="1.0" ?>
<!-- =================================================================================== -->
<!-- |    This document was autogenerated by xacro from /home/baudouin/catkin_ws/src/Manipulator/Files/Reach-Alpha-5-ROS/bpl_alpha_description/urdf/alpha_5_example.urdf.xacro | -->
<!-- |    EDITING THIS FILE BY HAND IS NOT RECOMMENDED                                 | -->
<!-- =================================================================================== -->
<robot name="alpha_5_example">
    <link name="world"/>
    <joint name="world_joint" type="fixed">
        <origin xyz="0 0 0" rpy="0 0 0"/>  <!-- Place the robot wherever you want -->
        <parent link="world"/>
        <child link="base_link"/>  <!-- replace this name with your robot's base link -->
    </joint>
    <link name="base_link" />
    <joint name="alpha_joint" type="fixed">
        <origin rpy="0 0 0" xyz="0 0 0" />
        <parent link="base_link" />
        <child link="alpha_base_link" />
        <origin rpy="0 0 0" xyz="0 0 0" />
    </joint>
    <material name="alpha_black">
        <color rgba="0.3 0.3 0.3 1" />
    </material>
    <link name="alpha_base_link" />
    <link name="alpha_m3_inline_link">
        <visual>
            <geometry>
                <mesh filename="package://bpl_alpha_description/meshes/M3-INLINE.stl" />
            </geometry>
            <origin rpy="0 0 0" xyz="0 0 0" />
            <material name="alpha_black" />
        </visual>
        <collision>
            <geometry>
                <cylinder length="0.150" radius="0.020" />
            </geometry>
            <origin rpy="0 1.57075 0" xyz="-0.075 0 0" />
        </collision>
        <inertial>
            <mass value="0.1" />
            <origin xyz="0 0 0" rpy="0 0 0" />
            <inertia ixx="0.03" iyy="0.03" izz="0.03" ixy="0.0" ixz="0.0" iyz="0.0" />
        </inertial>
    </link>
    <joint name="alpha_base_link_joint" type="fixed">
        <parent link="alpha_base_link" />
        <child link="alpha_m3_inline_link" />
        <origin rpy="0 0 0" />
    </joint>
    <link name="alpha_m2_1_1_link">
        <visual>
            <geometry>
                <mesh filename="package://bpl_alpha_description/meshes/M2-1-1.stl" />
            </geometry>
            <origin rpy="0 0 0" xyz="0 0 0" />
            <material name="alpha_black" />
        </visual>
        <collision>
            <geometry>
                <cylinder length="0.066" radius="0.020" />
            </geometry>
            <origin rpy="0 0 0" xyz="0 0 0.000" />
        </collision>
        <inertial>
            <mass value="0.1" />
            <origin xyz="0 0 0" rpy="0 0 0" />
            <inertia ixx="0.03" iyy="0.03" izz="0.03" ixy="0.0" ixz="0.0" iyz="0.0" />
        </inertial>
    </link>
    <joint name="alpha_axis_e" type="revolute">
        <parent link="alpha_m3_inline_link" />
        <child link="alpha_m2_1_1_link" />
        <origin xyz="0 0 0.014" />
        <axis xyz="0 0 1" />
        <limit effort="9.0" lower="0.0" upper="6.3" velocity="0.5" />
    </joint>
    <link name="alpha_m2_joint_link">
        <visual>
            <geometry>
                <mesh filename="package://bpl_alpha_description/meshes/M2.stl" />
            </geometry>
            <origin rpy="0 0 0" xyz="0 0 0" />
            <material name="alpha_black" />
        </visual>
        <collision>
            <geometry>
                <cylinder length="0.145" radius="0.020" />
            </geometry>
            <origin rpy="0 0 0" xyz="-0.02 0 -0.0725" />
        </collision>
        <collision>
            <geometry>
                <cylinder length="0.040" radius="0.020" />
            </geometry>
            <origin rpy="1.5707 0 0" xyz="0 0 0" />
        </collision>
        <collision>
            <geometry>
                <cylinder length="0.040" radius="0.020" />
            </geometry>
            <origin rpy="1.5707 0 0" xyz="-0.040 0 -0.1453" />
        </collision>
        <inertial>
            <mass value="0.1" />
            <origin xyz="0 0 0" rpy="0 0 0" />
            <inertia ixx="0.03" iyy="0.03" izz="0.03" ixy="0.0" ixz="0.0" iyz="0.0" />
        </inertial>
    </link>
    <joint name="alpha_axis_d" type="revolute">
        <parent link="alpha_m2_1_1_link" />
        <child link="alpha_m2_joint_link" />
        <origin xyz="-0.02 0 0.033" />
        <axis xyz="0 1 0" />
        <limit effort="9.0" lower="0.0" upper="3.8" velocity="0.5" />
    </joint>
    <link name="alpha_m2_1_2_link">
        <visual>
            <geometry>
                <mesh filename="package://bpl_alpha_description/meshes/M2-1-3.stl" />
            </geometry>
            <origin rpy="0 0 0" xyz="0 0 0" />
            <material name="alpha_black" />
        </visual>
        <collision>
            <geometry>
                <cylinder length="0.033" radius="0.020" />
            </geometry>
            <origin rpy="0 0 0" xyz="0.02 0 0.0165" />
        </collision>
        <inertial>
            <mass value="0.1" />
            <origin xyz="0 0 0" rpy="0 0 0" />
            <inertia ixx="0.03" iyy="0.03" izz="0.03" ixy="0.0" ixz="0.0" iyz="0.0" />
        </inertial>
    </link>
    <joint name="alpha_axis_c" type="revolute">
        <parent link="alpha_m2_joint_link" />
        <child link="alpha_m2_1_2_link" />
        <origin rpy="0 0 3.14159" xyz="-0.04 0 -0.1453" />
        <axis xyz="0 1 0" />
        <limit effort="9.0" lower="0.0" upper="3.5" velocity="0.5" />
    </joint>
    <link name="alpha_m1_link">
        <visual>
            <geometry>
                <mesh filename="package://bpl_alpha_description/meshes/RS1-100-101-123.stl" />
            </geometry>
            <origin rpy="0 -1.5707 0" xyz="0 0 0" />
            <material name="alpha_black" />
        </visual>
        <collision>
            <geometry>
                <cylinder length="0.10975" radius="0.020" />
            </geometry>
            <origin rpy="0 0 0" xyz="0.00 0 0.054875" />
        </collision>
        <inertial>
            <mass value="0.1" />
            <origin xyz="0 0 0" rpy="0 0 0" />
            <inertia ixx="0.03" iyy="0.03" izz="0.03" ixy="0.0" ixz="0.0" iyz="0.0" />
        </inertial>
    </link>
    <joint name="alpha_axis_b" type="revolute">
        <parent link="alpha_m2_1_2_link" />
        <child link="alpha_m1_link" />
        <origin rpy="0 0 2.09439" xyz="0.02 0 0.033" />
        <axis xyz="0 0 -1" />
        <limit effort="9.0" lower="0.0" upper="6.2" velocity="0.5" />
    </joint>
    <material name="alpha_jaws_black">
        <color rgba="0.3 0.3 0.3 1" />
    </material>
    <joint name="alpha_jaws_joint" type="fixed">
        <origin rpy="0 0 0" xyz="0 0 0.09975" />
        <parent link="alpha_m1_link" />
        <child link="alpha_jaws_base_link" />
    </joint>
    <link name="alpha_jaws_base_link" />
    <link name="alpha_push_rod" />
    <joint name="alpha_axis_a" type="prismatic">
        <origin rpy="0 0 0" xyz="0 0 0.009" />
        <parent link="alpha_jaws_base_link" />
        <child link="alpha_push_rod" />
        <axis xyz="0 0 1" />
        <limit effort="10" lower="0" upper="0.015" velocity="10" />
    </joint>
    <material name="alpha_standard_jaws_black">
        <color rgba="0.3 0.3 0.3 1" />
    </material>
    <joint name="alpha_standard_jaws_joint" type="fixed">
        <origin rpy="0 0 0" xyz="0 0 0" />
        <parent link="alpha_jaws_base_link" />
        <child link="alpha_standard_jaws_base_link" />
        <origin rpy="0 0 0" xyz="0 0 0" />
    </joint>
    <link name="alpha_standard_jaws_base_link">
        <visual>
            <geometry>
                <mesh filename="package://bpl_alpha_description/meshes/end_effectors/RS1-124.stl" />
            </geometry>
            <material name="alpha_standard_jaws_black" />
        </visual>
    </link>
    <link name="alpha_standard_jaws_rs1_130_link">
        <visual>
            <geometry>
                <mesh filename="package://bpl_alpha_description/meshes/end_effectors/RS1-130.stl" />
            </geometry>
            <material name="alpha_standard_jaws_black" />
            <origin rpy="0 0 0" xyz="0 0 0" />
        </visual>
        <collision>
            <geometry>
                <box size="0.012 0.03 0.09" />
            </geometry>
            <origin rpy="0 0 0" xyz="0.0 -0.008 0.045" />
        </collision>
        <inertial>
            <mass value="0.1" />
            <origin xyz="0 0 0" rpy="0 0 0" />
            <inertia ixx="0.03" iyy="0.03" izz="0.03" ixy="0.0" ixz="0.0" iyz="0.0" />
        </inertial>
    </link>
    <joint name="alpha_standard_jaws_rs1_130_joint" type="revolute">
        <origin rpy="0 0 0" xyz="0 0.0155 0.0069" />
        <parent link="alpha_standard_jaws_base_link" />
        <child link="alpha_standard_jaws_rs1_130_link" />
        <axis xyz="-1 0 0" />
        <limit effort="10" lower="0" upper="0.5" velocity="10" />
        <mimic joint="alpha_axis_a" multiplier="51" offset="0" />
    </joint>
    <link name="alpha_standard_jaws_rs1_139_link">
        <visual>
            <geometry>
                <mesh filename="package://bpl_alpha_description/meshes/end_effectors/RS1-139.stl" />
            </geometry>
            <material name="alpha_standard_jaws_black" />
            <origin rpy="0 0 0" xyz="0 0 0" />
        </visual>
        <collision>
            <geometry>
                <box size="0.012 0.03 0.09" />
            </geometry>
            <origin rpy="0 0 0" xyz="0.0 0.008 0.045" />
        </collision>
        <inertial>
            <mass value="0.1" />
            <origin xyz="0 0 0" rpy="0 0 0" />
            <inertia ixx="0.03" iyy="0.03" izz="0.03" ixy="0.0" ixz="0.0" iyz="0.0" />
        </inertial>
    </link>
    <joint name="alpha_standard_jaws_rs1_139_joint" type="revolute">
        <origin rpy="0 0 0" xyz="0 -0.0155 0.0069" />
        <parent link="alpha_standard_jaws_base_link" />
        <child link="alpha_standard_jaws_rs1_139_link" />
        <axis xyz="1 0 0" />
        <limit effort="10" lower="0" upper="0.5" velocity="10" />
        <mimic joint="alpha_standard_jaws_rs1_130_joint" multiplier="1" offset="0" />
    </joint>
    <transmission name="trans_alpha_axis_e">
        <type>transmission_interface/SimpleTransmission</type>
        <joint name="alpha_axis_e">
            <hardwareInterface>hardware_interface/EffortJointInterface</hardwareInterface>
        </joint>
        <actuator name="alpha_axis_e_motor">
            <hardwareInterface>hardware_interface/EffortJointInterface</hardwareInterface>
            <mechanicalReduction>1</mechanicalReduction>
        </actuator>
    </transmission>
    <transmission name="trans_alpha_axis_d">
        <type>transmission_interface/SimpleTransmission</type>
        <joint name="alpha_axis_d">
            <hardwareInterface>hardware_interface/EffortJointInterface</hardwareInterface>
        </joint>
        <actuator name="alpha_axis_d_motor">
            <hardwareInterface>hardware_interface/EffortJointInterface</hardwareInterface>
            <mechanicalReduction>1</mechanicalReduction>
        </actuator>
    </transmission>
    <transmission name="trans_alpha_axis_c">
        <type>transmission_interface/SimpleTransmission</type>
        <joint name="alpha_axis_c">
            <hardwareInterface>hardware_interface/EffortJointInterface</hardwareInterface>
        </joint>
        <actuator name="alpha_axis_c_motor">
            <hardwareInterface>hardware_interface/EffortJointInterface</hardwareInterface>
            <mechanicalReduction>1</mechanicalReduction>
        </actuator>
    </transmission>
    <transmission name="trans_alpha_axis_b">
        <type>transmission_interface/SimpleTransmission</type>
        <joint name="alpha_axis_b">
            <hardwareInterface>hardware_interface/EffortJointInterface</hardwareInterface>
        </joint>
        <actuator name="alpha_axis_b_motor">
            <hardwareInterface>hardware_interface/EffortJointInterface</hardwareInterface>
            <mechanicalReduction>1</mechanicalReduction>
        </actuator>
    </transmission>
    <transmission name="trans_alpha_axis_a">
        <type>transmission_interface/SimpleTransmission</type>
        <joint name="alpha_axis_a">
            <hardwareInterface>hardware_interface/EffortJointInterface</hardwareInterface>
        </joint>
        <actuator name="alpha_axis_a_motor">
            <hardwareInterface>hardware_interface/EffortJointInterface</hardwareInterface>
            <mechanicalReduction>1</mechanicalReduction>
        </actuator>
    </transmission>
    <transmission name="trans_alpha_standard_jaws_rs1_130_joint">
        <type>transmission_interface/SimpleTransmission</type>
        <joint name="alpha_standard_jaws_rs1_130_joint">
            <hardwareInterface>hardware_interface/EffortJointInterface</hardwareInterface>
        </joint>
        <actuator name="alpha_standard_jaws_rs1_130_joint_motor">
            <hardwareInterface>hardware_interface/EffortJointInterface</hardwareInterface>
            <mechanicalReduction>1</mechanicalReduction>
        </actuator>
    </transmission>
    <transmission name="trans_alpha_standard_jaws_rs1_139_joint">
        <type>transmission_interface/SimpleTransmission</type>
        <joint name="alpha_standard_jaws_rs1_139_joint">
            <hardwareInterface>hardware_interface/EffortJointInterface</hardwareInterface>
        </joint>
        <actuator name="alpha_standard_jaws_rs1_139_joint_motor">
            <hardwareInterface>hardware_interface/EffortJointInterface</hardwareInterface>
            <mechanicalReduction>1</mechanicalReduction>
        </actuator>
    </transmission>
    <gazebo>
        <plugin name="gazebo_ros_control" filename="libgazebo_ros_control.so">
            <robotNamespace>/alpha</robotNamespace>
            <robotSimType>gazebo_ros_control/DefaultRobotHWSim</robotSimType>
        </plugin>
    </gazebo>
</robot>

